Workbook

Sheet global
O1: A | P1: B
A2: ="QAPLU01" -> QAPLU01 | B2: A-PlusCal 20 X 250 gr | C2: 1042 | D2: Pack | E2: 52 | F2: Advansia Indotani, PT | H2: C | O2: A-PlusCal 20 X 250 gr | P2: =SUMIFS($C$2:$C$7959,$B$2:$B$7959,O2) -> 1042
A3: ="AAPLU01" -> AAPLU01 | B3: A-PlusCal 20 X 250 gr | C3: 0 | D3: Pcs | E3: 0 | O3: AC LG | P3: =SUMIFS($C$2:$C$7959,$B$2:$B$7959,O3) -> 0
A4: ="ZZACL01" -> ZZACL01 | B4: AC LG | C4: 0 | D4: Pcs | E4: 0 | F4: No Name | G4: Sarana Promosi | O4: AC Midea | P4: =SUMIFS($C$2:$C$7959,$B$2:$B$7959,O4) -> 0
A5: ="ZZACMI02" -> ZZACMI02 | B5: AC Midea | C5: 0 | D5: Pcs | E5: 0 | F5: No Name | G5: Sarana Promosi | O5: AC Mitsubishi | P5: =SUMIFS($C$2:$C$7959,$B$2:$B$7959,O5) -> 0
A6: ="ZZACMI01" -> ZZACMI01 | B6: AC Mitsubishi | C6: 0 | D6: Pcs | E6: 0 | F6: No Name | G6: Sarana Promosi | O6: ACL 6 865 SL 25 X 400 ml | P6: =SUMIFS($C$2:$C$7959,$B$2:$B$7959,O6) -> 0
A7: ="QACL02" -> QACL02 | B7: ACL 6 865 SL 25 X 400 ml | C7: 0 | D7: Btl | E7: 0 | F7: Asiana Chemicalindo Lestari, PT | G7: 2,4 D | H7: A | O7: ACL 6 865 SL 50 X 200 ml | P7: =SUMIFS($C$2:$C$7959,$B$2:$B$7959,O7) -> 141
A8: ="QACL01" -> QACL01 | B8: ACL 6 865 SL 50 X 200 ml | C8: 141 | D8: Btl | E8: 2 | F8: Asiana Chemicalindo Lestari, PT | G8: 2,4 D | H8: A | O8: Abacel 18 EC 10 X 1 ltr | P8: =SUMIFS($C$2:$C$7959,$B$2:$B$7959,O8) -> 1
A9: ="AABAC01" -> AABAC01 | B9: Abacel 18 EC 10 X 1 ltr | C9: 0 | D9: Btl | E9: 0 | F9: Excel Meg Indo, PT | G9: Abamectin | O9: Abacel 18 EC 20 X 500 ml | P9: =SUMIFS($C$2:$C$7959,$B$2:$B$7959,O9) -> 8730
A10: ="QABAC01" -> QABAC01 | B10: Abacel 18 EC 10 X 1 ltr | C10: 1 | D10: Btl | E10: 0 | F10: Excel Meg Indo, PT | G10: Abamectin | O10: Abacel 18 EC 40 X 250 ml | P10: =SUMIFS($C$2:$C$7959,$B$2:$B$7959,O10) -> 12653
A11: ="QABAC03" -> QABAC03 | B11: Abacel 18 EC 20 X 500 ml | C11: 8730 | D11: Btl | E11: 436 | F11: Excel Meg Indo, PT | G11: Abamectin | O11: Abacel 18 EC 50 X 100 ml | P11: =SUMIFS($C$2:$C$7959,$B$2:$B$7959,O11) -> 2999
A12: ="AABAC03" -> AABAC03 | B12: Abacel 18 EC 20 X 500 ml | C12: 0 | D12: Btl | E12: 0 | F12: Excel Meg Indo, PT | G12: Abamectin | O12: Abacell 18 EC 100 X 100 ml (tdk terpakai) | P12: =SUMIFS($C$2:$C$7959,$B$2:$B$7959,O12) -> 0
A13: ="QABAC04" -> QABAC04 | B13: Abacel 18 EC 40 X 250 ml | C13: 12653 | D13: Btl | E13: 316 | F13: Excel Meg Indo, PT | G13: Abamectin | O13: Abacell 18 EC 100 X 100 ml (tidak terpakai) | P13: =SUMIFS($C$2:$C$7959,$B$2:$B$7959,O13) -> 0
A14: ="AABAC04" -> AABAC04 | B14: Abacel 18 EC 40 X 250 ml | C14: 0 | D14: Btl | E14: 0 | F14: Excel Meg Indo, PT | G14: Abamectin | O14: Abacell 18 EC 50 X 100 ml | P14: =SUMIFS($C$2:$C$7959,$B$2:$B$7959,O14) -> 0
A15: ="AABAC09" -> AABAC09 | B15: Abacel 18 EC 50 X 100 ml | C15: 0 | D15: Btl | E15: 0 | O15: Abacyper 30/125 EC 24 X 200 ml | P15: =SUMIFS($C$2:$C$7959,$B$2:$B$7959,O15) -> 0
A16: ="QABAC07" -> QABAC07 | B16: Abacel 18 EC 50 X 100 ml | C16: 2999 | D16: Btl | E16: 59 | F16: Excel Meg Indo, PT | G16: Abamectin | O16: Abacyper 30/125 EC 48 X 100 ml | P16: =SUMIFS($C$2:$C$7959,$B$2:$B$7959,O16) -> 0
A17: ="QABAC02" -> QABAC02 | B17: Abacell 18 EC 100 X 100 ml (tdk terpakai) | C17: 0 | D17: Btl | E17: 0 | F17: Excel Meg Indo, PT | G17: Abamectin | O17: Abacypher Reform 100ml (Sample) | P17: =SUMIFS($C$2:$C$7959,$B$2:$B$7959,O17) -> 0
A18: ="AABAC02" -> AABAC02 | B18: Abacell 18 EC 100 X 100 ml (tidak terpakai) | C18: 0 | D18: Btl | E18: 0 | F18: Excel Meg Indo, PT | G18: Abamectin | O18: Abado 50 WP 20 X 20 X 10 gr | P18: =SUMIFS($C$2:$C$7959,$B$2:$B$7959,O18) -> 0
A19: ="AABAC07" -> AABAC07 | B19: Abacell 18 EC 50 X 100 ml | C19: 0 | D19: Btl | E19: 0 | F19: Excel Meg Indo, PT | G19: Abamectin | O19: Abado 50 WP 20 X 6 X 40 gr | P19: =SUMIFS($C$2:$C$7959,$B$2:$B$7959,O19) -> 480
A20: ="QABAC06" -> QABAC06 | B20: Abacyper 30/125 EC 24 X 200 ml | C20: 0 | D20: Btl | E20: 0 | F20: Artha Buana Mandiri/Graha Niaga Mandiri, CV | G20: Abamectin + Sipermetrin | O20: Abastar 290 SC 40 X 250 ml | P20: =SUMIFS($C$2:$C$7959,$B$2:$B$7959,O20) -> 0
A21: ="AABAC06" -> AABAC06 | B21: Abacyper 30/125 EC 24 X 200 ml | C21: 0 | D21: Btl | E21: 0 | F21: Artha Buana Mandiri/Graha Niaga Mandiri, CV | G21: Abamectin + Sipermetrin | O21: Abastar 290 SC 50 X 100 ml | P21: =SUMIFS($C$2:$C$7959,$B$2:$B$7959,O21) -> 0
A22: ="QABAC05" -> QABAC05 | B22: Abacyper 30/125 EC 48 X 100 ml | C22: 0 | D22: Btl | E22: 0 | F22: Artha Buana Mandiri/Graha Niaga Mandiri, CV | G22: Abamectin + Sipermetrin | O22: Abenz 22 EC 100 X 100 ml | P22: =SUMIFS($C$2:$C$7959,$B$2:$B$7959,O22) -> 80
A23: ="AABAC05" -> AABAC05 | B23: Abacyper 30/125 EC 48 X 100 ml | C23: 0 | D23: Btl | E23: 0 | F23: Artha Buana Mandiri/Graha Niaga Mandiri, CV | G23: Abamectin + Sipermetrin | O23: Abenz 22 EC 40 X 250 ml | P23: =SUMIFS($C$2:$C$7959,$B$2:$B$7959,O23) -> 3624
A24: ="AABAC08" -> AABAC08 | B24: Abacypher Reform 100ml (Sample) | C24: 0 | D24: Btl | E24: 0 | F24: Artha Buana Mandiri/Graha Niaga Mandiri, CV | G24: Abamectin + Sipermetrin | O24: Abojo 60 WP 10 X 20 X 50 gr | P24: =SUMIFS($C$2:$C$7959,$B$2:$B$7959,O24) -> 32993
A25: ="AABAD02" -> AABAD02 | B25: Abado 50 WP 20 X 20 X 10 gr | C25: 0 | D25: Pack | E25: 0 | F25: Advansia Indotani, PT | G25: Dimetomorf | H25: C | O25: Abojo 60 WP 100 X 100 gr | P25: =SUMIFS($C$2:$C$7959,$B$2:$B$7959,O25) -> 1000
A26: ="QABAD02" -> QABAD02 | B26: Abado 50 WP 20 X 20 X 10 gr | C26: 0 | D26: Pack | E26: 0 | F26: Advansia Indotani, PT | G26: Dimetomorf | H26: C | O26: Absina 36 EC 100 X 100 ml | P26: =SUMIFS($C$2:$C$7959,$B$2:$B$7959,O26) -> 0
A27: ="AABAD01" -> AABAD01 | B27: Abado 50 WP 20 X 6 X 40 gr | C27: 0 | D27: Pack | E27: 0 | F27: Advansia Indotani, PT | G27: Dimetomorf | H27: C | O27: Absina 36 EC 20 X 1 ltr | P27: =SUMIFS($C$2:$C$7959,$B$2:$B$7959,O27) -> 0
A28: ="QABAD01" -> QABAD01 | B28: Abado 50 WP 20 X 6 X 40 gr | C28: 480 | D28: Pack | E28: 4 | F28: Advansia Indotani, PT | G28: Dimetomorf | H28: C | O28: Absina 36 EC 20 X 500 ml | P28: =SUMIFS($C$2:$C$7959,$B$2:$B$7959,O28) -> 0
A29: ="QABAS02" -> QABAS02 | B29: Abastar 290 SC 40 X 250 ml | C29: 0 | D29: Btl | E29: 0 | F29: Excel Meg Indo, PT | G29: Abamertin + Klorpirofos | H29: C | O29: Absina 36 EC 50 X 200 ml | P29: =SUMIFS($C$2:$C$7959,$B$2:$B$7959,O29) -> 0
A30: ="QABAS01" -> QABAS01 | B30: Abastar 290 SC 50 X 100 ml | C30: 0 | D30: Btl | E30: 0 | F30: Excel Meg Indo, PT | G30: Abamertin + Klorpirofos | H30: C | O30: Abuki 50 SL 20 X 250 ml | P30: =SUMIFS($C$2:$C$7959,$B$2:$B$7959,O30) -> 0
A31: ="QABEN01" -> QABEN01 | B31: Abenz 22 EC 100 X 100 ml | C31: 80 | D31: Btl | E31: 0 | F31: Advansia Indotani, PT | G31: Amamektin Benzoat | O31: Abuki 50 SL 20 X 500 ml | P31: =SUMIFS($C$2:$C$7959,$B$2:$B$7959,O31) -> 0
A32: ="AABEN01" -> AABEN01 | B32: Abenz 22 EC 100 X 100 ml | C32: 0 | D32: Btl | E32: 0 | F32: Advansia Indotani, PT | G32: Amamektin Benzoat | O32: Abuki 50 SL 50 X 100 ml | P32: =SUMIFS($C$2:$C$7959,$B$2:$B$7959,O32) -> 0
A33: ="QABEN02" -> QABEN02 | B33: Abenz 22 EC 40 X 250 ml | C33: 3624 | D33: Btl | E33: 90 | F33: Advansia Indotani, PT | G33: Amamektin Benzoat | O33: Acapela System 280 SC 40 X 100 ml | P33: =SUMIFS($C$2:$C$7959,$B$2:$B$7959,O33) -> 0
A34: ="AABEN02" -> AABEN02 | B34: Abenz 22 EC 40 X 250 ml | C34: 0 | D34: Btl | E34: 0 | F34: Advansia Indotani, PT | G34: Amamektin Benzoat | O34: Acapela System 280 SC 50 X 100 ml | P34: =SUMIFS($C$2:$C$7959,$B$2:$B$7959,O34) -> 19204
A35: ="AABOJ02" -> AABOJ02 | B35: Abojo 60 WP 10 X 20 X 50 gr | C35: 0 | D35: Pack | E35: 0 | F35: Advansia Indotani, PT | G35: fentin asetat | O35: Accora 100 EC 15 X 1 ltr (Sample) | P35: =SUMIFS($C$2:$C$7959,$B$2:$B$7959,O35) -> 0
A36: ="QABOJ02" -> QABOJ02 | B36: Abojo 60 WP 10 X 20 X 50 gr | C36: 32993 | D36: Pack | E36: 164 | F36: Advansia Indotani, PT | G36: fentin asetat | O36: Accora 100 EC 15 X 1 ltr | P36: =SUMIFS($C$2:$C$7959,$B$2:$B$7959,O36) -> 0
A37: ="AABOJ01" -> AABOJ01 | B37: Abojo 60 WP 100 X 100 gr | C37: 0 | D37: Pack | E37: 0 | F37: Advansia Indotani, PT | G37: fentin asetat | O37: Accora 100 EC 20 X 500 ml | P37: =SUMIFS($C$2:$C$7959,$B$2:$B$7959,O37) -> 0
A38: ="AABOJO01" -> AABOJO01 | B38: Abojo 60 WP 100 X 100 gr | C38: 0 | D38: Pack | E38: 0 | O38: Accora 100 EC 50 X 100 ml | P38: =SUMIFS($C$2:$C$7959,$B$2:$B$7959,O38) -> 0
A39: ="QABOJ01" -> QABOJ01 | B39: Abojo 60 WP 100 X 100 gr | C39: 1000 | D39: Pack | E39: 10 | F39: Advansia Indotani, PT | G39: fentin asetat | O39: Accu Isatech Isa 8-12 | P39: =SUMIFS($C$2:$C$7959,$B$2:$B$7959,O39) -> 3
A40: ="QABSI01" -> QABSI01 | B40: Absina 36 EC 100 X 100 ml | C40: 0 | D40: Btl | E40: 0 | F40: Binangun Agro Lestari, CV | G40: Abamektin | H40: B | O40: Accu Isatech 8A - 12 Volt | P40: =SUMIFS($C$2:$C$7959,$B$2:$B$7959,O40) -> 0
...

Sheet lot
B2: KODE | C2: DESCRIPTION | D2: QTYLOT | E2: EXP
B3: AABAC03 | C3: Abacel 18 EC 20 X 500 ml | D3: 0 | E3: 47362
B4: AACCO03 | C4: Accora 100 EC 15 X 1 ltr (Sample) | D4: 0 | E4: 45658
B5: AACCU01 | C5: Accu Kayaba Kering 12A - 12 Volt | D5: 1 | E5: 1/1/1000
B6: AADRI02 | C6: Adrift 125 EC 50 X 100 ml | D6: 0 | E6: 45597
B7: AADRI02 | C7: Adrift 125 EC 50 X 100 ml | D7: 0 | E7: 46813
B8: AAFON01 | C8: Afonil 50 SC 40 X 250 ml | D8: 0 | E8: 46631
B9: AAFON01 | C9: Afonil 50 SC 40 X 250 ml | D9: 0 | E9: 46631
B10: AAGRI10 | C10: Agrimore E 20 X 500 gr | D10: 0 | E10: 1/1/1000
B11: AAGRI11 | C11: Agrimore K 20 X 500 gr - New | D11: 0 | E11: 1/1/1000
B12: AAGRI12 | C12: Agrimore N 20 X 500 gr - New | D12: 0 | E12: 1/1/1000
B13: AAGRI13 | C13: Agrimore P 20 X 500 gr | D13: 0 | E13: 1/1/1000
B14: AAGROM01 | C14: Agromil 710 EC 20 X 1 ltr | D14: 0 | E14: 1/1/1000
B15: AAGUS03 | C15: Agus 500 SC 100 X 100 ml | D15: 0 | E15: 46661
B16: AAGUS04 | C16: Agus 500 SC 40 X 250 ml | D16: 0 | E16: 46753
B17: AALAD01 | C17: Aladin 865 SL 20 X 400 ml | D17: 0 | E17: 1/1/1000
B18: AALAT06 | C18: Alat Kocor Pupuk Cair Quda Karisma 20 ltr | D18: 0 | E18: 1/1/1000
B19: AALAT09 | C19: Alat Kocor Pupuk Padat Quda Karisma 25 ltr | D19: 0 | E19: 1/1/1000
B20: AALMI01 | C20: Almix 247 ZC 40 X 250 ml | D20: 0 | E20: 1/1/1000
B21: AAMCO06 | C21: Amcothene 75 SP 25 Kg | D21: 0 | E21: 1/1/1000
B22: AAMCO07 | C22: Amco Up 486 SL 20 X 1 ltr | D22: 0 | E22: 47119
B23: AAMIB01 | C23: Amiboost Anti Stress 20 X 250 ml (Sample) | D23: 0 | E23: 45870
B24: AAMIB02 | C24: Amiboost Generative 20 X 250 ml | D24: 0 | E24: 45870
B25: AAMIB02 | C25: Amiboost Generative 20 X 250 ml | D25: 0 | E25: 45870
B26: AAMIB02 | C26: Amiboost Generative 20 X 250 ml | D26: 0 | E26: 45870
B27: AAMIB03 | C27: Amiboost Vegetative 20 X 250 ml | D27: 0 | E27: 45870
B28: AAMIB03 | C28: Amiboost Vegetative 20 X 250 ml | D28: 0 | E28: 45870
B29: AAMIB03 | C29: Amiboost Vegetative 20 X 250 ml | D29: 0 | E29: 45870
B30: AAMIB05 | C30: Amiboost Vegetative 10 X 1 ltr | D30: 0 | E30: 45992
B31: AAMIB05 | C31: Amiboost Vegetative 10 X 1 ltr | D31: 0 | E31: 46054
B32: AAMIC01 | C32: Amichlor 400 EC 100 ml | D32: 11 | E32: 1/1/1000
B33: AAMIN04 | C33: Aminosong Mango 500 ml (Sample) | D33: 4 | E33: 47150
B34: AAMIS01 | C34: Amistartop 325 SC 100 X 50 ml | D34: 0 | E34: 46508
B35: AAMIS04 | C35: Amistartop 325 SC 50 X 100 ml | D35: 0 | E35: 45778
B36: AAMIS04 | C36: Amistartop 325 SC 50 X 100 ml | D36: 0 | E36: 45778
B37: AAMOL01 | C37: Amolin 300 EC 100 X 100 ml | D37: 60 | E37: 46753
B38: AAMOL01 | C38: Amolin 300 EC 100 X 100 ml | D38: 0 | E38: 46296
B39: AAMOL02 | C39: Amolin 300 EC 40 X 250 ml | D39: 0 | E39: 47849
B40: AAREN02 | C40: Arendi 20/10 WP 20 X 20 X 25 gr | D40: 2 | E40: 46813
B41: AARIZ01 | C41: Arizona 55 EC 80 ml (Sample) | D41: 13 | E41: 1/1/1000
...

Sheet Sheet3
B1: NM | C1: QTY | J1: LOT | K1: =SUM(K3:K1324) -> 4995493 | N1: =SUM(N3:N1324) -> 6742236 | O1: =SUM(O3:O1324) -> 6742236 | P1: =N1-O1 -> 0.0010000002 | Y1: LOT | Z1: GLOBAL | AA1: COMPARE
M2: Nama Barang | N2: QTY GLOBAL | O2: QTY SISTEM | P2: STATUS
I3: Accu Kayaba Kering 12A - 12 Volt | J3: Accu Kayaba Kering 12A - 12 Volt1/1/1000 | K3: 1 | L3: =VLOOKUP(J3,'[1]stockopname_master_item (11)'!B$2:C$3427,2,0) -> #N/A | M3: A-PlusCal 20 X 250 gr | N3: 1042 | O3: =VLOOKUP(M3,[2]Sheet1!B$2:C$1721,2,0) -> 1042 | P3: =IF(O3-N3=0,"sama","tidak") -> sama | X3: Accu Kayaba Kering 12A - 12 Volt | Y3: 1 | Z3: 1 | AA3: =IF(Y3-Z3=0,"SAMA","TIDAK") -> SAMA | AC3: A-PlusCal 20 X 250 gr47484 | AD3: =VLOOKUP(AC3,$J$3:$K$1324,2,0) -> 2 | AE3: =IF(ISNA(AD3),"0",AD3) -> 2
I4: Adrift 125 EC 50 X 100 ml | J4: Adrift 125 EC 50 X 100 ml46813 | K4: 202 | L4: =VLOOKUP(J4,'[1]stockopname_master_item (11)'!B$2:C$3427,2,0) -> #N/A | M4: ACL 6 865 SL 50 X 200 ml | N4: 141 | O4: =VLOOKUP(M4,[2]Sheet1!B$2:C$1721,2,0) -> 141 | P4: =IF(O4-N4=0,"sama","tidak") -> sama | X4: Adrift 125 EC 50 X 100 ml | Y4: 202 | Z4: 202 | AA4: =IF(Y4-Z4=0,"SAMA","TIDAK") -> SAMA | AC4: A-PlusCal 20 X 250 gr47908 | AD4: =VLOOKUP(AC4,$J$3:$K$1324,2,0) -> 1040 | AE4: =IF(ISNA(AD4),"0",AD4) -> 1040
I5: Alat Kocor Pupuk Cair Quda Karisma 20 ltr | J5: Alat Kocor Pupuk Cair Quda Karisma 20 ltr1/1/1000 | K5: 258 | L5: =VLOOKUP(J5,'[1]stockopname_master_item (11)'!B$2:C$3427,2,0) -> #N/A | M5: Abacel 18 EC 10 X 1 ltr | N5: 1 | O5: =VLOOKUP(M5,[2]Sheet1!B$2:C$1721,2,0) -> 1 | P5: =IF(O5-N5=0,"sama","tidak") -> sama | X5: Alat Kocor Pupuk Cair Quda Karisma 20 ltr | Y5: 258 | Z5: 258 | AA5: =IF(Y5-Z5=0,"SAMA","TIDAK") -> SAMA | AC5: Abacel 18 EC 10 X 1 ltr46813 | AD5: =VLOOKUP(AC5,$J$3:$K$1324,2,0) -> #N/A | AE5: =IF(ISNA(AD5),"0",AD5) -> 0
I6: Alat Kocor Pupuk Padat Quda Karisma 25 ltr | J6: Alat Kocor Pupuk Padat Quda Karisma 25 ltr1/1/1000 | K6: 360 | L6: =VLOOKUP(J6,'[1]stockopname_master_item (11)'!B$2:C$3427,2,0) -> #N/A | M6: Abacel 18 EC 20 X 500 ml | N6: 8730 | O6: =VLOOKUP(M6,[2]Sheet1!B$2:C$1721,2,0) -> 8730 | P6: =IF(O6-N6=0,"sama","tidak") -> sama | X6: Alat Kocor Pupuk Padat Quda Karisma 25 ltr | Y6: 360 | Z6: 360 | AA6: =IF(Y6-Z6=0,"SAMA","TIDAK") -> SAMA | AC6: Abacel 18 EC 10 X 1 ltr46874 | AD6: =VLOOKUP(AC6,$J$3:$K$1324,2,0) -> #N/A | AE6: =IF(ISNA(AD6),"0",AD6) -> 0
I7: Amco Up 486 SL 20 X 1 ltr | J7: Amco Up 486 SL 20 X 1 ltr47119 | K7: 6 | L7: =VLOOKUP(J7,'[1]stockopname_master_item (11)'!B$2:C$3427,2,0) -> #N/A | M7: Abacel 18 EC 40 X 250 ml | N7: 12653 | O7: =VLOOKUP(M7,[2]Sheet1!B$2:C$1721,2,0) -> 12653 | P7: =IF(O7-N7=0,"sama","tidak") -> sama | X7: Amco Up 486 SL 20 X 1 ltr | Y7: 6538 | Z7: 6538 | AA7: =IF(Y7-Z7=0,"SAMA","TIDAK") -> SAMA | AC7: Abacel 18 EC 10 X 1 ltr46905 | AD7: =VLOOKUP(AC7,$J$3:$K$1324,2,0) -> 1 | AE7: =IF(ISNA(AD7),"0",AD7) -> 1
I8: Amichlor 400 EC 100 ml | J8: Amichlor 400 EC 100 ml1/1/1000 | K8: 11 | L8: =VLOOKUP(J8,'[1]stockopname_master_item (11)'!B$2:C$3427,2,0) -> #N/A | M8: Abacel 18 EC 50 X 100 ml | N8: 2999 | O8: =VLOOKUP(M8,[2]Sheet1!B$2:C$1721,2,0) -> 2999 | P8: =IF(O8-N8=0,"sama","tidak") -> sama | X8: Amichlor 400 EC 100 ml | Y8: 11 | Z8: 11 | AA8: =IF(Y8-Z8=0,"SAMA","TIDAK") -> SAMA | AC8: Abacel 18 EC 10 X 1 ltr46935 | AD8: =VLOOKUP(AC8,$J$3:$K$1324,2,0) -> #N/A | AE8: =IF(ISNA(AD8),"0",AD8) -> 0
I9: Aminosong Mango 500 ml (Sample) | J9: Aminosong Mango 500 ml (Sample)47150 | K9: 4 | L9: =VLOOKUP(J9,'[1]stockopname_master_item (11)'!B$2:C$3427,2,0) -> #N/A | M9: Abado 50 WP 20 X 6 X 40 gr | N9: 480 | O9: =VLOOKUP(M9,[2]Sheet1!B$2:C$1721,2,0) -> 480 | P9: =IF(O9-N9=0,"sama","tidak") -> sama | X9: Aminosong Mango 500 ml (Sample) | Y9: 4 | Z9: 4 | AA9: =IF(Y9-Z9=0,"SAMA","TIDAK") -> SAMA | AC9: Abacel 18 EC 10 X 1 ltr47027 | AD9: =VLOOKUP(AC9,$J$3:$K$1324,2,0) -> #N/A | AE9: =IF(ISNA(AD9),"0",AD9) -> 0
I10: Amolin 300 EC 100 X 100 ml | J10: Amolin 300 EC 100 X 100 ml46753 | K10: 2590 | L10: =VLOOKUP(J10,'[1]stockopname_master_item (11)'!B$2:C$3427,2,0) -> #N/A | M10: Abenz 22 EC 100 X 100 ml | N10: 80 | O10: =VLOOKUP(M10,[2]Sheet1!B$2:C$1721,2,0) -> 80 | P10: =IF(O10-N10=0,"sama","tidak") -> sama | X10: Amolin 300 EC 100 X 100 ml | Y10: 4890 | Z10: 4890 | AA10: =IF(Y10-Z10=0,"SAMA","TIDAK") -> SAMA | AC10: Abacel 18 EC 10 X 1 ltr47150 | AD10: =VLOOKUP(AC10,$J$3:$K$1324,2,0) -> #N/A | AE10: =IF(ISNA(AD10),"0",AD10) -> 0
I11: Amolin 300 EC 40 X 250 ml | J11: Amolin 300 EC 40 X 250 ml47849 | K11: 35 | L11: =VLOOKUP(J11,'[1]stockopname_master_item (11)'!B$2:C$3427,2,0) -> #N/A | M11: Abenz 22 EC 40 X 250 ml | N11: 3624 | O11: =VLOOKUP(M11,[2]Sheet1!B$2:C$1721,2,0) -> 3624 | P11: =IF(O11-N11=0,"sama","tidak") -> sama | X11: Amolin 300 EC 40 X 250 ml | Y11: 616 | Z11: 616 | AA11: =IF(Y11-Z11=0,"SAMA","TIDAK") -> SAMA | AC11: Abacel 18 EC 20 X 500 ml46935 | AD11: =VLOOKUP(AC11,$J$3:$K$1324,2,0) -> #N/A | AE11: =IF(ISNA(AD11),"0",AD11) -> 0
I12: Arendi 20/10 WP 20 X 20 X 25 gr | J12: Arendi 20/10 WP 20 X 20 X 25 gr46813 | K12: 2 | L12: =VLOOKUP(J12,'[1]stockopname_master_item (11)'!B$2:C$3427,2,0) -> #N/A | M12: Abojo 60 WP 10 X 20 X 50 gr | N12: 32993 | O12: =VLOOKUP(M12,[2]Sheet1!B$2:C$1721,2,0) -> 32993 | P12: =IF(O12-N12=0,"sama","tidak") -> sama | X12: Arendi 20/10 WP 20 X 20 X 25 gr | Y12: 3805 | Z12: 3805 | AA12: =IF(Y12-Z12=0,"SAMA","TIDAK") -> SAMA | AC12: Abacel 18 EC 20 X 500 ml47027 | AD12: =VLOOKUP(AC12,$J$3:$K$1324,2,0) -> #N/A | AE12: =IF(ISNA(AD12),"0",AD12) -> 0
I13: Arizona 55 EC 80 ml (Sample) | J13: Arizona 55 EC 80 ml (Sample)1/1/1000 | K13: 13 | L13: =VLOOKUP(J13,'[1]stockopname_master_item (11)'!B$2:C$3427,2,0) -> #N/A | M13: Abojo 60 WP 100 X 100 gr | N13: 1000 | O13: =VLOOKUP(M13,[2]Sheet1!B$2:C$1721,2,0) -> 1000 | P13: =IF(O13-N13=0,"sama","tidak") -> sama | X13: Arizona 55 EC 80 ml (Sample) | Y13: 13 | Z13: 13 | AA13: =IF(Y13-Z13=0,"SAMA","TIDAK") -> SAMA | AC13: Abacel 18 EC 20 X 500 ml47119 | AD13: =VLOOKUP(AC13,$J$3:$K$1324,2,0) -> #N/A | AE13: =IF(ISNA(AD13),"0",AD13) -> 0
I14: Arjuna 200 EC 50 X 80 ml | J14: Arjuna 200 EC 50 X 80 ml47270 | K14: 3 | L14: =VLOOKUP(J14,'[1]stockopname_master_item (11)'!B$2:C$3427,2,0) -> #N/A | M14: Acapela System 280 SC 50 X 100 ml | N14: 19204 | O14: =VLOOKUP(M14,[2]Sheet1!B$2:C$1721,2,0) -> 19204 | P14: =IF(O14-N14=0,"sama","tidak") -> sama | X14: Arjuna 200 EC 50 X 80 ml | Y14: 3 | Z14: 3 | AA14: =IF(Y14-Z14=0,"SAMA","TIDAK") -> SAMA | AC14: Abacel 18 EC 20 X 500 ml47178 | AD14: =VLOOKUP(AC14,$J$3:$K$1324,2,0) -> 8730 | AE14: =IF(ISNA(AD14),"0",AD14) -> 8730
... I346: Alika 247 ZC 50 X 100 ml | J346: Alika 247 ZC 50 X 100 ml46692 | K346: 7080 | L346: =VLOOKUP(J346,'[1]stockopname_master_item (11)'!B$2:C$3427,2,0) -> #N/A | M346: Ever Green Asam Amino 30 X 500 ml | N346: 4 | O346: =VLOOKUP(M346,[2]Sheet1!B$2:C$1721,2,0) -> 4 | P346: =IF(O346-N346=0,"sama","tidak") -> sama | X346: Bactocyn 150 AL 100 X 100 ml | Y346: 316 | Z346: 316 | AA346: =IF(Y346-Z346=0,"SAMA","TIDAK") -> SAMA | AC346: Beka Biang Kompos 25 X 250 ml44256 | AD346: =VLOOKUP(AC346,$J$3:$K$1324,2,0) -> #N/A | AE346: =IF(ISNA(AD346),"0",AD346) -> 0
I347: Alika 247 ZC 50 X 100 ml | J347: Alika 247 ZC 50 X 100 ml46722 | K347: 4350 | L347: =VLOOKUP(J347,'[1]stockopname_master_item (11)'!B$2:C$3427,2,0) -> #N/A | M347: Ever Green Asam Amino 40 X 250 ml | N347: 1909 | O347: =VLOOKUP(M347,[2]Sheet1!B$2:C$1721,2,0) -> 1909 | P347: =IF(O347-N347=0,"sama","tidak") -> sama | X347: Bag Jagung Q235 - 1 kg | Y347: 46374 | Z347: 64062 | AA347: =IF(Y347-Z347=0,"SAMA","TIDAK") -> TIDAK | AB347: supp | AC347: Bellator 265 SC 25 X 200 ml46813 | AD347: =VLOOKUP(AC347,$J$3:$K$1324,2,0) -> 95 | AE347: =IF(ISNA(AD347),"0",AD347) -> 95
I348: Almix 141/106 SC 50 X 100 ml | J348: Almix 141/106 SC 50 X 100 ml47515 | K348: 440 | L348: =VLOOKUP(J348,'[1]stockopname_master_item (11)'!B$2:C$3427,2,0) -> #N/A | M348: Ever Green Asam Humat 20 X 1 ltr | N348: 511 | O348: =VLOOKUP(M348,[2]Sheet1!B$2:C$1721,2,0) -> 511 | P348: =IF(O348-N348=0,"sama","tidak") -> sama | X348: Bag NPK Novatec 5 Kg | Y348: 43777 | Z348: 43777 | AA348: =IF(Y348-Z348=0,"SAMA","TIDAK") -> SAMA | AC348: Belt Expert 480 SC 20 X 250 ml46844 | AD348: =VLOOKUP(AC348,$J$3:$K$1324,2,0) -> #N/A | AE348: =IF(ISNA(AD348),"0",AD348) -> 0
I349: Almix 141/106 SC 40 X 250 ml | J349: Almix 141/106 SC 40 X 250 ml47696 | K349: 955 | L349: =VLOOKUP(J349,'[1]stockopname_master_item (11)'!B$2:C$3427,2,0) -> #N/A | M349: Ever Green Asam Humat 30 X 500 ml | N349: 571 | O349: =VLOOKUP(M349,[2]Sheet1!B$2:C$1721,2,0) -> 571 | P349: =IF(O349-N349=0,"sama","tidak") -> sama | X349: Bahsan 650 EC 100 X 80 ml | Y349: 891 | Z349: 891 | AA349: =IF(Y349-Z349=0,"SAMA","TIDAK") -> SAMA | AC349: Belt Expert 480 SC 20 X 250 ml46966 | AD349: =VLOOKUP(AC349,$J$3:$K$1324,2,0) -> #N/A | AE349: =IF(ISNA(AD349),"0",AD349) -> 0
I350: Almix 141/106 SC 20 X 500 ml | J350: Almix 141/106 SC 20 X 500 ml47696 | K350: 100 | L350: =VLOOKUP(J350,'[1]stockopname_master_item (11)'!B$2:C$3427,2,0) -> #N/A | M350: Ever Green Asam Humat 40 X 250 ml (Sample) | N350: 40 | O350: =VLOOKUP(M350,[2]Sheet1!B$2:C$1721,2,0) -> 40 | P350: =IF(O350-N350=0,"sama","tidak") -> sama | X350: Bahsan 650 EC 50 X 200 ml | Y350: 558 | Z350: 558 | AA350: =IF(Y350-Z350=0,"SAMA","TIDAK") -> SAMA | AC350: Belt Expert 480 SC 20 X 250 ml47178 | AD350: =VLOOKUP(AC350,$J$3:$K$1324,2,0) -> #N/A | AE350: =IF(ISNA(AD350),"0",AD350) -> 0
I351: Amabas 500 EC 16 X 1 ltr | J351: Amabas 500 EC 16 X 1 ltr47880 | K351: 11 | L351: =VLOOKUP(J351,'[1]stockopname_master_item (11)'!B$2:C$3427,2,0) -> #N/A | M351: Fan Nozzle | N351: 25 | O351: =VLOOKUP(M351,[2]Sheet1!B$2:C$1721,2,0) -> 25 | P351: =IF(O351-N351=0,"sama","tidak") -> sama | X351: Baledo 250/50 SC 40 X 100 ml | Y351: 560 | Z351: 560 | AA351: =IF(Y351-Z351=0,"SAMA","TIDAK") -> SAMA | AC351: Belt Yamaha1/1/1000 | AD351: =VLOOKUP(AC351,$J$3:$K$1324,2,0) -> 9 | AE351: =IF(ISNA(AD351),"0",AD351) -> 9
I352: Amabas 500 EC 20 X 400 ml | J352: Amabas 500 EC 20 X 400 ml47908 | K352: 12 | L352: =VLOOKUP(J352,'[1]stockopname_master_item (11)'!B$2:C$3427,2,0) -> #N/A | M352: Fargo 70 WP 20 X 500 gr | N352: 100 | O352: =VLOOKUP(M352,[2]Sheet1!B$2:C$1721,2,0) -> 100 | P352: =IF(O352-N352=0,"sama","tidak") -> sama | X352: Bamex 18 EC 100 X 50 ml (M2U) | Y352: 4158 | Z352: 4158 | AA352: =IF(Y352-Z352=0,"SAMA","TIDAK") -> SAMA | AC352: Ben Up 480 SL 20 ltr + 20 Pack Metaben 20 WG-5gr47849 | AD352: =VLOOKUP(AC352,$J$3:$K$1324,2,0) -> #N/A | AE352: =IF(ISNA(AD352),"0",AD352) -> 0
I353: Amabas 500 EC 20 X 400 ml | J353: Amabas 500 EC 20 X 400 ml47969 | K353: 1540 | L353: =VLOOKUP(J353,'[1]stockopname_master_item (11)'!B$2:C$3427,2,0) -> #N/A | M353: Fargo 70 WP 40 X 250 gr | N353: 140 | O353: =VLOOKUP(M353,[2]Sheet1!B$2:C$1721,2,0) -> 140 | P353: =IF(O353-N353=0,"sama","tidak") -> sama | X353: Bamex 18 EC 20 X 200 ml (M2U) | Y353: 285 | Z353: 285 | AA353: =IF(Y353-Z353=0,"SAMA","TIDAK") -> SAMA | AC353: Ben Up 480 SL 20 X 1 ltr + 1 Pack Metaben 20 WG-5gr47849 | AD353: =VLOOKUP(AC353,$J$3:$K$1324,2,0) -> #N/A | AE353: =IF(ISNA(AD353),"0",AD353) -> 0
I354: Ambest 100 ME 50 X 100 ml | J354: Ambest 100 ME 50 X 100 ml47270 | K354: 270 | L354: =VLOOKUP(J354,'[1]stockopname_master_item (11)'!B$2:C$3427,2,0) -> #N/A | M354: Fenprozole 500 EC 48 X 240 ml | N354: 576 | O354: =VLOOKUP(M354,[2]Sheet1!B$2:C$1721,2,0) -> 576 | P354: =IF(O354-N354=0,"sama","tidak") -> sama | X354: Basfoliar Combi Stipp 20 X 500 ml | Y354: 1460 | Z354: 1460 | AA354: =IF(Y354-Z354=0,"SAMA","TIDAK") -> SAMA | AC354: Ben Up 480 SL 4 X 5 ltr + 5 Pack Metaben 20 WG-5gr47849 | AD354: =VLOOKUP(AC354,$J$3:$K$1324,2,0) -> #N/A | AE354: =IF(ISNA(AD354),"0",AD354) -> 0
I355: Ambest 100 ME 40 X 250 ml | J355: Ambest 100 ME 40 X 250 ml47270 | K355: 250 | L355: =VLOOKUP(J355,'[1]stockopname_master_item (11)'!B$2:C$3427,2,0) -> #N/A | M355: Fentolin 200 EC 20 X 500 ml | N355: 904 | O355: =VLOOKUP(M355,[2]Sheet1!B$2:C$1721,2,0) -> 904 | P355: =IF(O355-N355=0,"sama","tidak") -> sama | X355: Basgent 55 SC 50 X 100 ml | Y355: 2964 | Z355: 2964 | AA355: =IF(Y355-Z355=0,"SAMA","TIDAK") -> SAMA | AC355: Benabel Plus 120/35 SC 48 X 250 ml47818 | AD355: =VLOOKUP(AC355,$J$3:$K$1324,2,0) -> #N/A | AE355: =IF(ISNA(AD355),"0",AD355) -> 0
I356: Amco Up 486 SL 20 X 1 ltr | J356: Amco Up 486 SL 20 X 1 ltr47058 | K356: 6527 | L356: =VLOOKUP(J356,'[1]stockopname_master_item (11)'!B$2:C$3427,2,0) -> #N/A | M356: Fenval 200 EC 15 X 1 ltr | N356: 764 | O356: =VLOOKUP(M356,[2]Sheet1!B$2:C$1721,2,0) -> 764 | P356: =IF(O356-N356=0,"sama","tidak") -> sama | X356: Basgent 55 SC 50 X 250 ml | Y356: 1971 | Z356: 1971 | AA356: =IF(Y356-Z356=0,"SAMA","TIDAK") -> SAMA | AC356: Benabel Plus 120/35 SC 48 X 250 ml47880 | AD356: =VLOOKUP(AC356,$J$3:$K$1324,2,0) -> 65 | AE356: =IF(ISNA(AD356),"0",AD356) -> 65
I357: Amco Up 486 SL 20 X 1 ltr | J357: Amco Up 486 SL 20 X 1 ltr47150 | K357: 5 | L357: =VLOOKUP(J357,'[1]stockopname_master_item (11)'!B$2:C$3427,2,0) -> #N/A | M357: Fenval 200 EC 20 X 250 ml | N357: 3340 | O357: =VLOOKUP(M357,[2]Sheet1!B$2:C$1721,2,0) -> 3340 | P357: =IF(O357-N357=0,"sama","tidak") -> sama | X357: Basgent 55 SC 20 X 500 ml | Y357: 505 | Z357: 505 | AA357: =IF(Y357-Z357=0,"SAMA","TIDAK") -> SAMA | AC357: Benabel Plus 120/35 SC 48 X 250 ml47908 | AD357: =VLOOKUP(AC357,$J$3:$K$1324,2,0) -> 1344 | AE357: =IF(ISNA(AD357),"0",AD357) -> 1344
I358: Amegu 200 SL 20 X 1 ltr | J358: Amegu 200 SL 20 X 1 ltr47757 | K358: 16 | L358: =VLOOKUP(J358,'[1]stockopname_master_item (11)'!B$2:C$3427,2,0) -> #N/A | M358: Fenval 200 EC 20 X 500 ml | N358: 17130 | O358: =VLOOKUP(M358,[2]Sheet1!B$2:C$1721,2,0) -> 17130 | P358: =IF(O358-N358=0,"sama","tidak") -> sama | X358: Basrata 150 SL 20 X 500 ml | Y358: 19 | Z358: 19 | AA358: =IF(Y358-Z358=0,"SAMA","TIDAK") -> SAMA | AC358: Benabel Plus 120/35 SC 64 X 100 ml47818 | AD358: =VLOOKUP(AC358,$J$3:$K$1324,2,0) -> 34 | AE358: =IF(ISNA(AD358),"0",AD358) -> 34
I359: Amegu 200 SL 20 X 1 ltr | J359: Amegu 200 SL 20 X 1 ltr47939 | K359: 2640 | L359: =VLOOKUP(J359,'[1]stockopname_master_item (11)'!B$2:C$3427,2,0) -> #N/A | M359: Fenval 200 EC 50 X 100 ml | N359: 5099 | O359: =VLOOKUP(M359,[2]Sheet1!B$2:C$1721,2,0) -> 5099 | P359: =IF(O359-N359=0,"sama","tidak") -> sama | X359: Basrata 150 SL 20 X 1 ltr | Y359: 1728 | Z359: 1728 | AA359: =IF(Y359-Z359=0,"SAMA","TIDAK") -> SAMA | AC359: Benang Pe mlg1/1/1000 | AD359: =VLOOKUP(AC359,$J$3:$K$1324,2,0) -> 3775 | AE359: =IF(ISNA(AD359),"0",AD359) -> 3775
... I374: Ampang 240 SL 20 X 1 ltr | J374: Ampang 240 SL 20 X 1 ltr47880 | K374: 1440 | L374: =VLOOKUP(J374,'[1]stockopname_master_item (11)'!B$2:C$3427,2,0) -> #N/A | M374: Fortune 250 ml | N374: 5 | O374: =VLOOKUP(M374,[2]Sheet1!B$2:C$1721,2,0) -> 5 | P374: =IF(O374-N374=0,"sama","tidak") -> sama | X374: Betasticker 80 X 30 ml | Y374: 320 | Z374: 320 | AA374: =IF(Y374-Z374=0,"SAMA","TIDAK") -> SAMA | AC374: Bestar 200 SL 20 X 1 ltr47969 | AD374: =VLOOKUP(AC374,$J$3:$K$1324,2,0) -> 5540 | AE374: =IF(ISNA(AD374),"0",AD374) -> 5540
I375: Amuron 70 EC 100 X 100 ml | J375: Amuron 70 EC 100 X 100 ml46600 | K375: 13 | L375: =VLOOKUP(J375,'[1]stockopname_master_item (11)'!B$2:C$3427,2,0) -> #N/A | M375: Fost Up 486 SL 20 X 1 ltr + 1 pack Pilly 5 gr | N375: 2860 | O375: =VLOOKUP(M375,[2]Sheet1!B$2:C$1721,2,0) -> 2860 | P375: =IF(O375-N375=0,"sama","tidak") -> sama | X375: Biggrow 20 WP 6 X 50 X 5 gr | Y375: 193047 | Z375: 191350 | AA375: =IF(Y375-Z375=0,"SAMA","TIDAK") -> TIDAK | AB375: x | AC375: Bestdonk 530 SL 20 X 1 ltr47849 | AD375: =VLOOKUP(AC375,$J$3:$K$1324,2,0) -> #N/A | AE375: =IF(ISNA(AD375),"0",AD375) -> 0
I376: Amuron 70 EC 40 X 250 ml | J376: Amuron 70 EC 40 X 250 ml47849 | K376: 235 | L376: =VLOOKUP(J376,'[1]stockopname_master_item (11)'!B$2:C$3427,2,0) -> #N/A | M376: Fruitka 50%K2O - 18%S 10 X 1 kg | N376: 137 | O376: =VLOOKUP(M376,[2]Sheet1!B$2:C$1721,2,0) -> 137 | P376: =IF(O376-N376=0,"sama","tidak") -> sama | X376: Biochems Vit B1+B6 20 X 1 ltr | Y376: 152 | Z376: 152 | AA376: =IF(Y376-Z376=0,"SAMA","TIDAK") -> SAMA | AC376: Besvidor 25 WP 4 X 25 X 100 gr46539 | AD376: =VLOOKUP(AC376,$J$3:$K$1324,2,0) -> 5 | AE376: =IF(ISNA(AD376),"0",AD376) -> 5
I377: Android 72 EC 20 X 400 ml | J377: Android 72 EC 20 X 400 ml46631 | K377: 400 | L377: =VLOOKUP(J377,'[1]stockopname_master_item (11)'!B$2:C$3427,2,0) -> #N/A | M377: Futay-1 (Padi) 10 X 1 ltr | N377: 980 | O377: =VLOOKUP(M377,[2]Sheet1!B$2:C$1721,2,0) -> 980 | P377: =IF(O377-N377=0,"sama","tidak") -> sama | X377: Biochems Vit B1+B6 30 X 500 ml | Y377: 760 | Z377: 760 | AA377: =IF(Y377-Z377=0,"SAMA","TIDAK") -> SAMA | AC377: Betasticker 80 X 30 ml1/1/1000 | AD377: =VLOOKUP(AC377,$J$3:$K$1324,2,0) -> 320 | AE377: =IF(ISNA(AD377),"0",AD377) -> 320
I378: Aneto 50 EC 50 X 100 ml | J378: Aneto 50 EC 50 X 100 ml47270 | K378: 1000 | L378: =VLOOKUP(J378,'[1]stockopname_master_item (11)'!B$2:C$3427,2,0) -> #N/A | M378: Futay-1 (Padi) 10 X 1 ltr + Kaos | N378: 261 | O378: =VLOOKUP(M378,[2]Sheet1!B$2:C$1721,2,0) -> 261 | P378: =IF(O378-N378=0,"sama","tidak") -> sama | X378: Biochems Vit B1+B6 40 X 250 ml | Y378: 855 | Z378: 855 | AA378: =IF(Y378-Z378=0,"SAMA","TIDAK") -> SAMA | AC378: Biggrow 20 WP 6 X 50 X 5 gr47849 | AD378: =VLOOKUP(AC378,$J$3:$K$1324,2,0) -> 1500 | AE378: =IF(ISNA(AD378),"0",AD378) -> 1500
I379: Aneto 50 EC 50 X 100 ml | J379: Aneto 50 EC 50 X 100 ml46508 | K379: 4 | L379: =VLOOKUP(J379,'[1]stockopname_master_item (11)'!B$2:C$3427,2,0) -> #N/A | M379: Futay-1 (Padi) 30 X 500 ml | N379: 2850 | O379: =VLOOKUP(M379,[2]Sheet1!B$2:C$1721,2,0) -> 2850 | P379: =IF(O379-N379=0,"sama","tidak") -> sama | X379: Bion M 1/48 WP 20 X 500 gr | Y379: 2880 | Z379: 2880 | AA379: =IF(Y379-Z379=0,"SAMA","TIDAK") -> SAMA | AC379: Biggrow 20 WP 6 X 50 X 5 gr48214 | AD379: =VLOOKUP(AC379,$J$3:$K$1324,2,0) -> 191547 | AE379: =IF(ISNA(AD379),"0",AD379) -> 191547
I380: Aneto 50 EC 30 X 500 ml + 2 pcs Neptune 8 gr | J380: Aneto 50 EC 30 X 500 ml + 2 pcs Neptune 8 gr46997 | K380: 794 | L380: =VLOOKUP(J380,'[1]stockopname_master_item (11)'!B$2:C$3427,2,0) -> #N/A | M380: Futay-1 (Padi) 50 X 100 ml KARISMA (Sample) | N380: 139 | O380: =VLOOKUP(M380,[2]Sheet1!B$2:C$1721,2,0) -> 139 | P380: =IF(O380-N380=0,"sama","tidak") -> sama | X380: Bionik 400 EC 20 X 500 ml | Y380: 2441 | Z380: 2441 | AA380: =IF(Y380-Z380=0,"SAMA","TIDAK") -> SAMA | AC380: Biochem Umum 30 X 500 ml1/1/1000 | AD380: =VLOOKUP(AC380,$J$3:$K$1324,2,0) -> #N/A | AE380: =IF(ISNA(AD380),"0",AD380) -> 0
I381: Aneto 50 EC 50 X 250 ml + 1 pcs Neptune 8 gr | J381: Aneto 50 EC 50 X 250 ml + 1 pcs Neptune 8 gr46874 | K381: 641 | L381: =VLOOKUP(J381,'[1]stockopname_master_item (11)'!B$2:C$3427,2,0) -> #N/A | M381: Futay-1 30 X 500 ml | N381: 203 | O381: =VLOOKUP(M381,[2]Sheet1!B$2:C$1721,2,0) -> 203 | P381: =IF(O381-N381=0,"sama","tidak") -> sama | X381: Bionik 400 EC 50 X 100 ml | Y381: 4309 | Z381: 4309 | AA381: =IF(Y381-Z381=0,"SAMA","TIDAK") -> SAMA | AC381: Biochem Umum 30 X 500 ml47696 | AD381: =VLOOKUP(AC381,$J$3:$K$1324,2,0) -> #N/A | AE381: =IF(ISNA(AD381),"0",AD381) -> 0
I382: Antramix 30/22.5 SG 100 X 100 gr | J382: Antramix 30/22.5 SG 100 X 100 gr46539 | K382: 993 | L382: =VLOOKUP(J382,'[1]stockopname_master_item (11)'!B$2:C$3427,2,0) -> #N/A | M382: Futay-1 50 X 100 ml | N382: 247 | O382: =VLOOKUP(M382,[2]Sheet1!B$2:C$1721,2,0) -> 247 | P382: =IF(O382-N382=0,"sama","tidak") -> sama | X382: Biosoft 20 X 1 ltr | Y382: 64 | Z382: 64 | AA382: =IF(Y382-Z382=0,"SAMA","TIDAK") -> SAMA | AC382: Biochems Vit B1+B6 20 X 1 ltr47757 | AD382: =VLOOKUP(AC382,$J$3:$K$1324,2,0) -> #N/A | AE382: =IF(ISNA(AD382),"0",AD382) -> 0
I383: A-PlusCal 20 X 250 gr | J383: A-PlusCal 20 X 250 gr47484 | K383: 2 | L383: =VLOOKUP(J383,'[1]stockopname_master_item (11)'!B$2:C$3427,2,0) -> #N/A | M383: Futay-1 50 X 250 ml | N383: 4476 | O383: =VLOOKUP(M383,[2]Sheet1!B$2:C$1721,2,0) -> 4476 | P383: =IF(O383-N383=0,"sama","tidak") -> sama | X383: Biosoft 50 X 100 ml | Y383: 110 | Z383: 110 | AA383: =IF(Y383-Z383=0,"SAMA","TIDAK") -> SAMA | AC383: Biochems Vit B1+B6 20 X 1 ltr47818 | AD383: =VLOOKUP(AC383,$J$3:$K$1324,2,0) -> 152 | AE383: =IF(ISNA(AD383),"0",AD383) -> 152
I384: A-PlusCal 20 X 250 gr | J384: A-PlusCal 20 X 250 gr47908 | K384: 1040 | L384: =VLOOKUP(J384,'[1]stockopname_master_item (11)'!B$2:C$3427,2,0) -> #N/A | M384: Futay-2 (Jagung) 10 X 1 ltr | N384: 90 | O384: =VLOOKUP(M384,[2]Sheet1!B$2:C$1721,2,0) -> 90 | P384: =IF(O384-N384=0,"sama","tidak") -> sama | X384: Blacer Booster Buah 25.79 L 24 X 500 ml | Y384: 984 | Z384: 984 | AA384: =IF(Y384-Z384=0,"SAMA","TIDAK") -> SAMA | AC384: Biochems Vit B1+B6 25 X 250 ml (Sample)47788 | AD384: =VLOOKUP(AC384,$J$3:$K$1324,2,0) -> #N/A | AE384: =IF(ISNA(AD384),"0",AD384) -> 0
I385: Applaud 10 WP 20 X 5 X 100 gr | J385: Applaud 10 WP 20 X 5 X 100 gr47574 | K385: 48 | L385: =VLOOKUP(J385,'[1]stockopname_master_item (11)'!B$2:C$3427,2,0) -> #N/A | M385: Futay-2 (Jagung) 10 X 1 ltr + Kaos | N385: 180 | O385: =VLOOKUP(M385,[2]Sheet1!B$2:C$1721,2,0) -> 180 | P385: =IF(O385-N385=0,"sama","tidak") -> sama | X385: Blacer Booster Daun 16.85 L 24 X 500 ml | Y385: 1362 | Z385: 1362 | AA385: =IF(Y385-Z385=0,"SAMA","TIDAK") -> SAMA | AC385: Biochems Vit B1+B6 30 X 500 ml47543 | AD385: =VLOOKUP(AC385,$J$3:$K$1324,2,0) -> 143 | AE385: =IF(ISNA(AD385),"0",AD385) -> 143
...

Sheet Sheet7
B2: Bag Jagung Q235 - 1 kg | C2: 46374 | D2: 64062 | E2: TIDAK | F2: supp | G2: 17688
B3: Biggrow 20 WP 6 X 50 X 5 gr | C3: 193047 | D3: 191350 | E3: TIDAK | F3: x | G3: -1697
B4: Decis 25 EC 100 X 50 ml | C4: 13293 | D4: 10793 | E4: TIDAK | F4: x | G4: -2500
B5: Kaos Java Karlos | C5: 637 | D5: 639 | E5: TIDAK | F5: x | G5: 2
B6: Karung OPP Lami 10 kg Qiu Seed | C6: 17908 | D6: 18322 | E6: TIDAK | F6: supp | G6: 414
B7: Sinergy 300 EC 40 X 250 ml | C7: 1122 | D7: 451 | E7: TIDAK | F7: x | G7: -671
B8: Tali Surya | C8: 0.001 | D8: 0.001 | E8: TIDAK | F8: x | G8: 4.5472003e-13
B9: Kaos Lengan Panjang Q235 | C9: 8081 | D9: 13843 | E9: TIDAK | F9: supp | G9: 5762

Sheet Sheet4
F2: Accu Kayaba Kering 12A - 12 Volt1/1/1000 | G2: 1
F3: Adrift 125 EC 50 X 100 ml46813 | G3: 202
F4: Alat Kocor Pupuk Cair Quda Karisma 20 ltr1/1/1000 | G4: 258
F5: Alat Kocor Pupuk Padat Quda Karisma 25 ltr1/1/1000 | G5: 360
F6: Amco Up 486 SL 20 X 1 ltr47119 | G6: 6
F7: Amichlor 400 EC 100 ml1/1/1000 | G7: 11
F8: Aminosong Mango 500 ml (Sample)47150 | G8: 4
F9: Amolin 300 EC 100 X 100 ml46753 | G9: 2590
F10: Amolin 300 EC 40 X 250 ml47849 | G10: 35
F11: Arendi 20/10 WP 20 X 20 X 25 gr46813 | G11: 2
F12: Arizona 55 EC 80 ml (Sample)1/1/1000 | G12: 13
F13: Arjuna 200 EC 50 X 80 ml47270 | G13: 3
... F1866: Zentech Poster Ambest Kutu Kebul1/1/1000 | G1866: 40

Sheet Sheet5
B2: Kembali ke dailystock
B4: KODE | C4: DESCRIPTION | D4: UNIT | E4: NAMAGUDANG | F4: KELOMPOK | G4: JENIS | H4: MERK | I4: QTY | J4: QTYLOT | K4: NOMOR_LOT | L4: TGLPRODUKSI | M4: TGLKADALUARSA | N4: SUPPLIER
B5: AABAC03 | C5: Abacel 18 EC 20 X 500 ml | D5: Btl | E5: Gdg. Induk | F5: Obat | G5: Insektisida | H5: Abacel 18 EC | I5: 0 | J5: 0 | K5: 2409011 | L5: 45756 | M5: 47362 | N5: Excel Meg Indo, PT
B6: AACCO03 | C6: Accora 100 EC 15 X 1 ltr (Sample) | D6: Btl | E6: Gdg. Induk | F6: No Group | G6: No Group | H6: No Group | I6: 0 | J6: 0 | K6: 2020 | L6: 44958 | M6: 45658 | N6: Sarana Tani Indonesia Makmur, PT
B7: AACCU01 | C7: Accu Kayaba Kering 12A - 12 Volt | D7: Pcs | E7: Gdg. Induk | F7: Sarana Pertanian | G7: Sarana Pertanian | H7: No Group | I7: 1 | J7: 1 | K7: 0 | L7: 44958 | M7: 1/1/1000 | N7: Widjaya, UD
B8: AADRI02 | C8: Adrift 125 EC 50 X 100 ml | D8: Btl | E8: Gdg. Induk | F8: No Group | G8: No Group | H8: No Group | I8: 0 | J8: 0 | K8: 6833 | L8: 45700 | M8: 45597 | N8: Bioworld Biosciencen ML, PT
B9: AADRI02 | C9: Adrift 125 EC 50 X 100 ml | D9: Btl | E9: Gdg. Induk | F9: No Group | G9: No Group | H9: No Group | I9: 0 | J9: 0 | K9: 8833 | L9: 45698 | M9: 46813 | N9: Bioworld Biosciencen ML, PT
B10: AAFON01 | C10: Afonil 50 SC 40 X 250 ml | D10: Btl | E10: Gdg. Induk | F10: Obat | G10: Insektisida | H10: Afonil 50 SC | I10: 0 | J10: 0 | K10: 2103001 | L10: 44958 | M10: 46631 | N10: Advansia Indotani, PT
B11: AAFON01 | C11: Afonil 50 SC 40 X 250 ml | D11: Btl | E11: Gdg. Induk | F11: Obat | G11: Insektisida | H11: Afonil 50 SC | I11: 0 | J11: 0 | K11: 2111055 | L11: 44958 | M11: 46631 | N11: Advansia Indotani, PT
B12: AAGRI10 | C12: Agrimore E 20 X 500 gr | D12: Pack | E12: Gdg. Induk | F12: No Group | G12: No Group | H12: No Group | I12: 0 | J12: 0 | K12: 0 | L12: 45831 | M12: 1/1/1000 | N12: -
B13: AAGRI11 | C13: Agrimore K 20 X 500 gr - New | D13: Pack | E13: Gdg. Induk | F13: No Group | G13: No Group | H13: No Group | I13: 0 | J13: 0 | K13: 0 | L13: 45831 | M13: 1/1/1000 | N13: -
B14: AAGRI12 | C14: Agrimore N 20 X 500 gr - New | D14: Pack | E14: Gdg. Induk | F14: No Group | G14: No Group | H14: No Group | I14: 0 | J14: 0 | K14: 0 | L14: 45831 | M14: 1/1/1000 | N14: -
B15: AAGRI13 | C15: Agrimore P 20 X 500 gr | D15: Pack | E15: Gdg. Induk | F15: No Group | G15: No Group | H15: No Group | I15: 0 | J15: 0 | K15: 0 | L15: 45831 | M15: 1/1/1000 | N15: -
B16: AAGROM01 | C16: Agromil 710 EC 20 X 1 ltr | D16: Btl | E16: Gdg. Induk | F16: No Group | G16: No Group | H16: No Group | I16: 0 | J16: 0 | K16: 0 | L16: 45797 | M16: 1/1/1000 | N16: -
B17: AAGUS03 | C17: Agus 500 SC 100 X 100 ml* | D17: Btl | E17: Gdg. Induk | F17: No Group | G17: No Group | H17: No Group | I17: 0 | J17: 0 | K17: ADV271E050 | L17: 45715 | M17: 46661 | N17: -
B18: AAGUS04 | C18: Agus 500 SC 40 X 250 ml* | D18: Btl | E18: Gdg. Induk | F18: No Group | G18: No Group | H18: No Group | I18: 0 | J18: 0 | K18: ADV003056 | L18: 45715 | M18: 46753 | N18: -
B19: AALAD01 | C19: Aladin 865 SL 20 X 400 ml | D19: Btl | E19: Gdg. Induk | F19: No Group | G19: No Group | H19: No Group | I19: 0 | J19: 0 | K19: 0 | L19: 45831 | M19: 1/1/1000 | N19: -
B20: AALAT06 | C20: Alat Kocor Pupuk Cair Quda Karisma 20 ltr* | D20: Pcs | E20: Gdg. Induk | F20: No Group | G20: No Group | H20: No Group | I20: 0 | J20: 0 | K20: 0 | L20: 45843 | M20: 1/1/1000 | N20: Sarana Tani Makmur, CV
B21: AALAT09 | C21: Alat Kocor Pupuk Padat Quda Karisma 25 ltr* | D21: Pcs | E21: Gdg. Induk | F21: No Group | G21: No Group | H21: No Group | I21: 0 | J21: 0 | K21: 0 | L21: 45843 | M21: 1/1/1000 | N21: Sarana Tani Makmur, CV
B22: AALMI01 | C22: Almix 247 ZC 40 X 250 ml* | D22: Btl | E22: Gdg. Induk | F22: No Group | G22: No Group | H22: No Group | I22: 0 | J22: 0 | K22: 0 | L22: 45824 | M22: 1/1/1000 | N22: -
B23: AAMCO06 | C23: Amcothene 75 SP 25 Kg | D23: Pack | E23: Gdg. Induk | F23: No Group | G23: No Group | H23: No Group | I23: 0 | J23: 0 | K23: 0 | L23: 45804 | M23: 1/1/1000 | N23: -
B24: AAMCO07 | C24: Amco Up 486 SL 20 X 1 ltr* | D24: Btl | E24: Gdg. Induk | F24: No Group | G24: No Group | H24: No Group | I24: 0 | J24: 0 | K24: 222200074 | L24: 45831 | M24: 47119 | N24: -
B25: AAMIB01 | C25: Amiboost Anti Stress 20 X 250 ml (Sample) | D25: Btl | E25: Gdg. Induk | F25: No Group | G25: No Group | H25: No Group | I25: 0 | J25: 0 | K25: 0 | L25: 44958 | M25: 45870 | N25: Cheil Jedang Indonesia, PT
B26: AAMIB02 | C26: Amiboost Generative 20 X 250 ml | D26: Btl | E26: Gdg. Expired | F26: No Group | G26: No Group | H26: No Group | I26: 0 | J26: 0 | K26: 0 | L26: 44958 | M26: 45870 | N26: Cheil Jedang Indonesia, PT
B27: AAMIB02 | C27: Amiboost Generative 20 X 250 ml | D27: Btl | E27: Gdg. Induk | F27: No Group | G27: No Group | H27: No Group | I27: 0 | J27: 0 | K27: 0 | L27: 44958 | M27: 45870 | N27: Cheil Jedang Indonesia, PT
B28: AAMIB02 | C28: Amiboost Generative 20 X 250 ml | D28: Btl | E28: Gdg. Ttp Kanvas | F28: No Group | G28: No Group | H28: No Group | I28: 0 | J28: 0 | K28: 0 | L28: 44958 | M28: 45870 | N28: Cheil Jedang Indonesia, PT
B29: AAMIB03 | C29: Amiboost Vegetative 20 X 250 ml | D29: Btl | E29: Gdg. Expired | F29: No Group | G29: No Group | H29: No Group | I29: 0 | J29: 0 | K29: 0 | L29: 44958 | M29: 45870 | N29: Cheil Jedang Indonesia, PT
B30: AAMIB03 | C30: Amiboost Vegetative 20 X 250 ml | D30: Btl | E30: Gdg. Induk | F30: No Group | G30: No Group | H30: No Group | I30: 0 | J30: 0 | K30: 0 | L30: 44958 | M30: 45870 | N30: Cheil Jedang Indonesia, PT
B31: AAMIB03 | C31: Amiboost Vegetative 20 X 250 ml | D31: Btl | E31: Gdg. Ttp Kanvas | F31: No Group | G31: No Group | H31: No Group | I31: 0 | J31: 0 | K31: 0 | L31: 44958 | M31: 45870 | N31: Cheil Jedang Indonesia, PT
B32: AAMIB05 | C32: Amiboost Vegetative 10 X 1 ltr* | D32: Btl | E32: Gdg. Induk | F32: No Group | G32: No Group | H32: No Group | I32: 0 | J32: 0 | K32: 0 | L32: 44958 | M32: 45992 | N32: Cheil Jedang Indonesia, PT
B33: AAMIB05 | C33: Amiboost Vegetative 10 X 1 ltr* | D33: Btl | E33: Gdg. Induk | F33: No Group | G33: No Group | H33: No Group | I33: 0 | J33: 0 | K33: 0 | L33: 45695 | M33: 46054 | N33: Cheil Jedang Indonesia, PT
B34: AAMIC01 | C34: Amichlor 400 EC 100 ml | D34: Btl | E34: Gdg. Induk | F34: No Group | G34: No Group | H34: No Group | I34: 11 | J34: 11 | K34: 0 | L34: 44958 | M34: 1/1/1000 | N34: Trimarga Nusantara Indonesia, PT
B35: AAMIN04 | C35: Aminosong Mango 500 ml (Sample) | D35: Btl | E35: Gdg. Induk | F35: No Group | G35: No Group | H35: No Group | I35: 4 | J35: 4 | K35: 81432Y6002 | L35: 44958 | M35: 47150 | N35: Agro Guna Makmur, PT
B36: AAMIS01 | C36: Amistartop 325 SC 100 X 50 ml | D36: Btl | E36: Gdg. Induk | F36: Obat | G36: Fungisida | H36: No Group | I36: 0 | J36: 0 | K36: JAK4ES1142 | L36: 44958 | M36: 46508 | N36: Syngenta Indonesia, PT
B37: AAMIS04 | C37: Amistartop 325 SC 50 X 100 ml | D37: Btl | E37: Gdg. Expired | F37: No Group | G37: No Group | H37: No Group | I37: 0 | J37: 0 | K37: ZAK2DS1285 | L37: 45817 | M37: 45778 | N37: -
B38: AAMIS04 | C38: Amistartop 325 SC 50 X 100 ml | D38: Btl | E38: Gdg. Induk | F38: No Group | G38: No Group | H38: No Group | I38: 0 | J38: 0 | K38: ZAK2DS1285 | L38: 45817 | M38: 45778 | N38: -
B39: AAMOL01 | C39: Amolin 300 EC 100 X 100 ml* | D39: Btl | E39: Gdg. Induk | F39: Obat | G39: Fungisida | H39: No Group | I39: 60 | J39: 60 | K39: ADV010V017 | L39: 45717 | M39: 46753 | N39: Advansia Indotani, PT
B40: AAMOL01 | C40: Amolin 300 EC 100 X 100 ml* | D40: Btl | E40: Gdg. Induk | F40: Obat | G40: Fungisida | H40: No Group | I40: 60 | J40: 0 | K40: ADV297H015 | L40: 44958 | M40: 46296 | N40: Advansia Indotani, PT
B41: AAMOL02 | C41: Amolin 300 EC 40 X 250 ml* | D41: Btl | E41: Gdg. Induk | F41: Obat | G41: Fungisida | H41: No Group | I41: 0 | J41: 0 | K41: ADV0121042 | L41: 46132 | M41: 47849 | N41: Advansia Indotani, PT
B42: AAREN02 | C42: Arendi 20/10 WP 20 X 20 X 25 gr* | D42: Pack | E42: Gdg. Induk | F42: No Group | G42: No Group | H42: No Group | I42: 2 | J42: 2 | K42: ADV0540240323ST | L42: 45843 | M42: 46813 | N42: Advansia Indotani, PT
...

Sheet Sheet6
E1: a | F1: b | L1: a | M1: b | Q1: a | R1: b | S1: c | T1: d | U1: e
B2: Accu Kayaba Kering 12A - 12 Volt1/1/1000 | C2: 1 | E2: A-PlusCal 20 X 250 gr47484 | F2: =VLOOKUP(E2,$B$2:$C$1866,2,0) -> 2 | G2: =IF(ISNA(F2),"0",F2) -> 2 | L2: A-PlusCal 20 X 250 gr47484 | M2: =VLOOKUP(L2,lot!$A$3:$E$13372,3,0) -> #N/A | Q2: Accu Kayaba Kering 12A - 12 Volt1/1/1000 | R2: 1 | S2: AACCU01 | T2: =VLOOKUP(Q2,lot!$A$3:$E$13372,3,0) -> #N/A | U2: =VLOOKUP(Q2,lot!$A$3:$E$13372,5,0) -> #N/A
B3: Adrift 125 EC 50 X 100 ml46813 | C3: 202 | E3: A-PlusCal 20 X 250 gr47908 | F3: =VLOOKUP(E3,$B$2:$C$1866,2,0) -> 1040 | G3: =IF(ISNA(F3),"0",F3) -> 1040 | L3: A-PlusCal 20 X 250 gr47908 | M3: =VLOOKUP(L3,lot!$A$3:$E$13372,3,0) -> #N/A | Q3: Adrift 125 EC 50 X 100 ml46813 | R3: 202 | S3: QADRI01 | T3: =VLOOKUP(Q3,lot!$A$3:$E$13372,3,0) -> #N/A | U3: =VLOOKUP(Q3,lot!$A$3:$E$13372,5,0) -> #N/A
B4: Alat Kocor Pupuk Cair Quda Karisma 20 ltr1/1/1000 | C4: 258 | E4: Abacel 18 EC 10 X 1 ltr46813 | F4: =VLOOKUP(E4,$B$2:$C$1866,2,0) -> #N/A | G4: =IF(ISNA(F4),"0",F4) -> 0 | L4: Abacel 18 EC 10 X 1 ltr46813 | M4: =VLOOKUP(L4,lot!$A$3:$E$13372,3,0) -> #N/A | Q4: Alat Kocor Pupuk Cair Quda Karisma 20 ltr1/1/1000 | R4: 258 | S4: QALAT07 | T4: =VLOOKUP(Q4,lot!$A$3:$E$13372,3,0) -> #N/A | U4: =VLOOKUP(Q4,lot!$A$3:$E$13372,5,0) -> #N/A
B5: Alat Kocor Pupuk Padat Quda Karisma 25 ltr1/1/1000 | C5: 360 | E5: Abacel 18 EC 10 X 1 ltr46874 | F5: =VLOOKUP(E5,$B$2:$C$1866,2,0) -> #N/A | G5: =IF(ISNA(F5),"0",F5) -> 0 | L5: Abacel 18 EC 10 X 1 ltr46874 | M5: =VLOOKUP(L5,lot!$A$3:$E$13372,3,0) -> #N/A | Q5: Alat Kocor Pupuk Padat Quda Karisma 25 ltr1/1/1000 | R5: 360 | S5: QALAT06 | T5: =VLOOKUP(Q5,lot!$A$3:$E$13372,3,0) -> #N/A | U5: =VLOOKUP(Q5,lot!$A$3:$E$13372,5,0) -> #N/A
B6: Amco Up 486 SL 20 X 1 ltr47119 | C6: 6 | E6: Abacel 18 EC 10 X 1 ltr46905 | F6: =VLOOKUP(E6,$B$2:$C$1866,2,0) -> 1 | G6: =IF(ISNA(F6),"0",F6) -> 1 | L6: Abacel 18 EC 10 X 1 ltr46905 | M6: =VLOOKUP(L6,lot!$A$3:$E$13372,3,0) -> #N/A | Q6: Amco Up 486 SL 20 X 1 ltr47119 | R6: 6 | S6: QAMCO17 | T6: =VLOOKUP(Q6,lot!$A$3:$E$13372,3,0) -> #N/A | U6: =VLOOKUP(Q6,lot!$A$3:$E$13372,5,0) -> #N/A
B7: Amichlor 400 EC 100 ml1/1/1000 | C7: 11 | E7: Abacel 18 EC 10 X 1 ltr46935 | F7: =VLOOKUP(E7,$B$2:$C$1866,2,0) -> #N/A | G7: =IF(ISNA(F7),"0",F7) -> 0 | L7: Abacel 18 EC 10 X 1 ltr46935 | M7: =VLOOKUP(L7,lot!$A$3:$E$13372,3,0) -> #N/A | Q7: Amichlor 400 EC 100 ml1/1/1000 | R7: 11 | S7: AAMIC01 | T7: =VLOOKUP(Q7,lot!$A$3:$E$13372,3,0) -> #N/A | U7: =VLOOKUP(Q7,lot!$A$3:$E$13372,5,0) -> #N/A
B8: Aminosong Mango 500 ml (Sample)47150 | C8: 4 | E8: Abacel 18 EC 10 X 1 ltr47027 | F8: =VLOOKUP(E8,$B$2:$C$1866,2,0) -> #N/A | G8: =IF(ISNA(F8),"0",F8) -> 0 | L8: Abacel 18 EC 10 X 1 ltr47027 | M8: =VLOOKUP(L8,lot!$A$3:$E$13372,3,0) -> #N/A | Q8: Aminosong Mango 500 ml (Sample)47150 | R8: 4 | S8: AAMIN04 | T8: =VLOOKUP(Q8,lot!$A$3:$E$13372,3,0) -> #N/A | U8: =VLOOKUP(Q8,lot!$A$3:$E$13372,5,0) -> #N/A
B9: Amolin 300 EC 100 X 100 ml46753 | C9: 2590 | E9: Abacel 18 EC 10 X 1 ltr47150 | F9: =VLOOKUP(E9,$B$2:$C$1866,2,0) -> #N/A | G9: =IF(ISNA(F9),"0",F9) -> 0 | L9: Abacel 18 EC 10 X 1 ltr47150 | M9: =VLOOKUP(L9,lot!$A$3:$E$13372,3,0) -> #N/A | Q9: Amolin 300 EC 100 X 100 ml46753 | R9: 2590 | S9: AAMOL01 | T9: =VLOOKUP(Q9,lot!$A$3:$E$13372,3,0) -> #N/A | U9: =VLOOKUP(Q9,lot!$A$3:$E$13372,5,0) -> #N/A
B10: Amolin 300 EC 40 X 250 ml47849 | C10: 35 | E10: Abacel 18 EC 20 X 500 ml46935 | F10: =VLOOKUP(E10,$B$2:$C$1866,2,0) -> #N/A | G10: =IF(ISNA(F10),"0",F10) -> 0 | L10: Abacel 18 EC 20 X 500 ml46935 | M10: =VLOOKUP(L10,lot!$A$3:$E$13372,3,0) -> #N/A | Q10: Amolin 300 EC 40 X 250 ml47849 | R10: 35 | S10: AAMOL02 | T10: =VLOOKUP(Q10,lot!$A$3:$E$13372,3,0) -> #N/A | U10: =VLOOKUP(Q10,lot!$A$3:$E$13372,5,0) -> #N/A
B11: Arendi 20/10 WP 20 X 20 X 25 gr46813 | C11: 2 | E11: Abacel 18 EC 20 X 500 ml47027 | F11: =VLOOKUP(E11,$B$2:$C$1866,2,0) -> #N/A | G11: =IF(ISNA(F11),"0",F11) -> 0 | L11: Abacel 18 EC 20 X 500 ml47027 | M11: =VLOOKUP(L11,lot!$A$3:$E$13372,3,0) -> #N/A | Q11: Arendi 20/10 WP 20 X 20 X 25 gr46813 | R11: 2 | S11: QAREN01 | T11: =VLOOKUP(Q11,lot!$A$3:$E$13372,3,0) -> #N/A | U11: =VLOOKUP(Q11,lot!$A$3:$E$13372,5,0) -> #N/A
B12: Arizona 55 EC 80 ml (Sample)1/1/1000 | C12: 13 | E12: Abacel 18 EC 20 X 500 ml47119 | F12: =VLOOKUP(E12,$B$2:$C$1866,2,0) -> #N/A | G12: =IF(ISNA(F12),"0",F12) -> 0 | L12: Abacel 18 EC 20 X 500 ml47119 | M12: =VLOOKUP(L12,lot!$A$3:$E$13372,3,0) -> #N/A | Q12: Arizona 55 EC 80 ml (Sample)1/1/1000 | R12: 13 | S12: AARIZ01 | T12: =VLOOKUP(Q12,lot!$A$3:$E$13372,3,0) -> #N/A | U12: =VLOOKUP(Q12,lot!$A$3:$E$13372,5,0) -> #N/A
B13: Arjuna 200 EC 50 X 80 ml47270 | C13: 3 | E13: Abacel 18 EC 20 X 500 ml47178 | F13: =VLOOKUP(E13,$B$2:$C$1866,2,0) -> 8730 | G13: =IF(ISNA(F13),"0",F13) -> 8730 | L13: Abacel 18 EC 20 X 500 ml47178 | M13: =VLOOKUP(L13,lot!$A$3:$E$13372,3,0) -> #N/A | Q13: Arjuna 200 EC 50 X 80 ml47270 | R13: 3 | S13: QARJU02 | T13: =VLOOKUP(Q13,lot!$A$3:$E$13372,3,0) -> #N/A | U13: =VLOOKUP(Q13,lot!$A$3:$E$13372,5,0) -> #N/A
... B81: Grandally 25 WP 25 gr1/1/1000 | C81: 33533 | E81: Agrogibb 40 SL 30 X 15 X 35 ml47757 | F81: =VLOOKUP(E81,$B$2:$C$1866,2,0) -> #N/A | G81: =IF(ISNA(F81),"0",F81) -> 0 | L81: Agrogibb 40 SL 30 X 15 X 35 ml47757 | M81: =VLOOKUP(L81,lot!$A$3:$E$13372,3,0) -> #N/A | Q81: Grandally 25 WP 25 gr1/1/1000 | R81: 33533 | S81: QGRAN01 | T81: =VLOOKUP(Q81,lot!$A$3:$E$13372,3,0) -> #N/A | U81: =VLOOKUP(Q81,lot!$A$3:$E$13372,5,0) -> #N/A
B82: Gunting Gland 7" Lady Pruner 05-219 12 X 1 pcs1/1/1000 | C82: 49 | E82: Agrogibb 40 SL 30 X 15 X 35 ml47908 | F82: =VLOOKUP(E82,$B$2:$C$1866,2,0) -> #N/A | G82: =IF(ISNA(F82),"0",F82) -> 0 | L82: Agrogibb 40 SL 30 X 15 X 35 ml47908 | M82: =VLOOKUP(L82,lot!$A$3:$E$13372,3,0) -> #N/A | Q82: Gunting Gland 7" Lady Pruner 05-219 12 X 1 pcs1/1/1000 | R82: 49 | S82: #N/A | T82: =VLOOKUP(Q82,lot!$A$3:$E$13372,3,0) -> #N/A | U82: =VLOOKUP(Q82,lot!$A$3:$E$13372,5,0) -> #N/A
B83: GW Magicgro G6 48 X 248 ml (Sampel)1/1/1000 | C83: 96 | E83: Agrogibb 40 SL 30 X 15 X 35 ml47939 | F83: =VLOOKUP(E83,$B$2:$C$1866,2,0) -> 10760 | G83: =IF(ISNA(F83),"0",F83) -> 10760 | L83: Agrogibb 40 SL 30 X 15 X 35 ml47939 | M83: =VLOOKUP(L83,lot!$A$3:$E$13372,3,0) -> #N/A | Q83: GW Magicgro G6 48 X 248 ml (Sampel)1/1/1000 | R83: 96 | S83: AGWMA03 | T83: =VLOOKUP(Q83,lot!$A$3:$E$13372,3,0) -> #N/A | U83: =VLOOKUP(Q83,lot!$A$3:$E$13372,5,0) -> #N/A
B84: GW Sanilan 12 X 998 ml1/1/1000 | C84: 21 | E84: Agus 500 SC 100 X 100 ml47088 | F84: =VLOOKUP(E84,$B$2:$C$1866,2,0) -> #N/A | G84: =IF(ISNA(F84),"0",F84) -> 0 | L84: Agus 500 SC 100 X 100 ml47088 | M84: =VLOOKUP(L84,lot!$A$3:$E$13372,3,0) -> #N/A | Q84: GW Sanilan 12 X 998 ml1/1/1000 | R84: 21 | S84: AGWSA01 | T84: =VLOOKUP(Q84,lot!$A$3:$E$13372,3,0) -> #N/A | U84: =VLOOKUP(Q84,lot!$A$3:$E$13372,5,0) -> #N/A
B85: GW Vit B1+B6 100 X 100 ml1/1/1000 | C85: 86 | E85: Agus 500 SC 100 X 100 ml47119 | F85: =VLOOKUP(E85,$B$2:$C$1866,2,0) -> #N/A | G85: =IF(ISNA(F85),"0",F85) -> 0 | L85: Agus 500 SC 100 X 100 ml47119 | M85: =VLOOKUP(L85,lot!$A$3:$E$13372,3,0) -> #N/A | Q85: GW Vit B1+B6 100 X 100 ml1/1/1000 | R85: 86 | S85: AGWVI02 | T85: =VLOOKUP(Q85,lot!$A$3:$E$13372,3,0) -> #N/A | U85: =VLOOKUP(Q85,lot!$A$3:$E$13372,5,0) -> #N/A
B86: Handstarter Star Metal1/1/1000 | C86: 11 | E86: Agus 500 SC 100 X 100 ml47178 | F86: =VLOOKUP(E86,$B$2:$C$1866,2,0) -> 6 | G86: =IF(ISNA(F86),"0",F86) -> 6 | L86: Agus 500 SC 100 X 100 ml47178 | M86: =VLOOKUP(L86,lot!$A$3:$E$13372,3,0) -> #N/A | Q86: Handstarter Star Metal1/1/1000 | R86: 11 | S86: QHAND01 | T86: =VLOOKUP(Q86,lot!$A$3:$E$13372,3,0) -> #N/A | U86: =VLOOKUP(Q86,lot!$A$3:$E$13372,5,0) -> #N/A
B87: Hernab 100 EC 1 ltr1/1/1000 | C87: 4 | E87: Agus 500 SC 100 X 100 ml47209 | F87: =VLOOKUP(E87,$B$2:$C$1866,2,0) -> 17900 | G87: =IF(ISNA(F87),"0",F87) -> 17900 | L87: Agus 500 SC 100 X 100 ml47209 | M87: =VLOOKUP(L87,lot!$A$3:$E$13372,3,0) -> #N/A | Q87: Hernab 100 EC 1 ltr1/1/1000 | R87: 4 | S87: AHERN01 | T87: =VLOOKUP(Q87,lot!$A$3:$E$13372,3,0) -> #N/A | U87: =VLOOKUP(Q87,lot!$A$3:$E$13372,5,0) -> #N/A
B88: Hijau 250 ml45200 | C88: 4 | E88: Agus 500 SC 40 X 250 ml47088 | F88: =VLOOKUP(E88,$B$2:$C$1866,2,0) -> #N/A | G88: =IF(ISNA(F88),"0",F88) -> 0 | L88: Agus 500 SC 40 X 250 ml47088 | M88: =VLOOKUP(L88,lot!$A$3:$E$13372,3,0) -> #N/A | Q88: Hijau 250 ml45200 | R88: 4 | S88: AHIJA01 | T88: =VLOOKUP(Q88,lot!$A$3:$E$13372,3,0) -> #N/A | U88: =VLOOKUP(Q88,lot!$A$3:$E$13372,5,0) -> #N/A
B89: HiPro Series 13-7-10 Powder 250 gr (Sample)1/1/1000 | C89: 8 | E89: Agus 500 SC 40 X 250 ml47119 | F89: =VLOOKUP(E89,$B$2:$C$1866,2,0) -> #N/A | G89: =IF(ISNA(F89),"0",F89) -> 0 | L89: Agus 500 SC 40 X 250 ml47119 | M89: =VLOOKUP(L89,lot!$A$3:$E$13372,3,0) -> #N/A | Q89: HiPro Series 13-7-10 Powder 250 gr (Sample)1/1/1000 | R89: 8 | S89: AHIPR01 | T89: =VLOOKUP(Q89,lot!$A$3:$E$13372,3,0) -> #N/A | U89: =VLOOKUP(Q89,lot!$A$3:$E$13372,5,0) -> #N/A
B90: Hoky 30 EC 16 X 1 ltr47270 | C90: 269 | E90: Agus 500 SC 40 X 250 ml47178 | F90: =VLOOKUP(E90,$B$2:$C$1866,2,0) -> #N/A | G90: =IF(ISNA(F90),"0",F90) -> 0 | L90: Agus 500 SC 40 X 250 ml47178 | M90: =VLOOKUP(L90,lot!$A$3:$E$13372,3,0) -> #N/A | Q90: Hoky 30 EC 16 X 1 ltr47270 | R90: 269 | S90: QHOKK03 | T90: =VLOOKUP(Q90,lot!$A$3:$E$13372,3,0) -> #N/A | U90: =VLOOKUP(Q90,lot!$A$3:$E$13372,5,0) -> #N/A
B91: I-Aba SP 250 ml (Sample)1/1/1000 | C91: 3 | E91: Agus 500 SC 40 X 250 ml47209 | F91: =VLOOKUP(E91,$B$2:$C$1866,2,0) -> 18 | G91: =IF(ISNA(F91),"0",F91) -> 18 | L91: Agus 500 SC 40 X 250 ml47209 | M91: =VLOOKUP(L91,lot!$A$3:$E$13372,3,0) -> #N/A | Q91: I-Aba SP 250 ml (Sample)1/1/1000 | R91: 3 | S91: AIABA01 | T91: =VLOOKUP(Q91,lot!$A$3:$E$13372,3,0) -> #N/A | U91: =VLOOKUP(Q91,lot!$A$3:$E$13372,5,0) -> #N/A
B92: I-Lu Tol 100ml (Sample)1/1/1000 | C92: 4 | E92: Agus 500 SC 40 X 250 ml47239 | F92: =VLOOKUP(E92,$B$2:$C$1866,2,0) -> 8440 | G92: =IF(ISNA(F92),"0",F92) -> 8440 | L92: Agus 500 SC 40 X 250 ml47239 | M92: =VLOOKUP(L92,lot!$A$3:$E$13372,3,0) -> #N/A | Q92: I-Lu Tol 100ml (Sample)1/1/1000 | R92: 4 | S92: AILUT01 | T92: =VLOOKUP(Q92,lot!$A$3:$E$13372,3,0) -> #N/A | U92: =VLOOKUP(Q92,lot!$A$3:$E$13372,5,0) -> #N/A
B93: Imuno 20 x 250 ml1/1/1000 | C93: 8 | E93: Agxanazol 200/150 SC 20 X 250 ml47058 | F93: =VLOOKUP(E93,$B$2:$C$1866,2,0) -> #N/A | G93: =IF(ISNA(F93),"0",F93) -> 0 | L93: Agxanazol 200/150 SC 20 X 250 ml47058 | M93: =VLOOKUP(L93,lot!$A$3:$E$13372,3,0) -> #N/A | Q93: Imuno 20 x 250 ml1/1/1000 | R93: 8 | S93: AIMUN01 | T93: =VLOOKUP(Q93,lot!$A$3:$E$13372,3,0) -> #N/A | U93: =VLOOKUP(Q93,lot!$A$3:$E$13372,5,0) -> #N/A
B94: I-Sad 250 ml (Sample)1/1/1000 | C94: 3 | E94: Agxanazol 200/150 SC 20 X 250 ml47209 | F94: =VLOOKUP(E94,$B$2:$C$1866,2,0) -> #N/A | G94: =IF(ISNA(F94),"0",F94) -> 0 | L94: Agxanazol 200/150 SC 20 X 250 ml47209 | M94: =VLOOKUP(L94,lot!$A$3:$E$13372,3,0) -> #N/A | Q94: I-Sad 250 ml (Sample)1/1/1000 | R94: 3 | S94: AISAD01 | T94: =VLOOKUP(Q94,lot!$A$3:$E$13372,3,0) -> #N/A | U94: =VLOOKUP(Q94,lot!$A$3:$E$13372,5,0) -> #N/A
... B100: Jet Stik Sprayer1/1/1000 | C100: 8 | E100: Akalis 550 SC 40 X 250 ml46631 | F100: =VLOOKUP(E100,$B$2:$C$1866,2,0) -> 1037 | G100: =IF(ISNA(F100),"0",F100) -> 1037 | L100: Akalis 550 SC 40 X 250 ml46631 | M100: =VLOOKUP(L100,lot!$A$3:$E$13372,3,0) -> #N/A | Q100: Jet Stik Sprayer1/1/1000 | R100: 8 | S100: AJET 01 | T100: =VLOOKUP(Q100,lot!$A$3:$E$13372,3,0) -> #N/A | U100: =VLOOKUP(Q100,lot!$A$3:$E$13372,5,0) -> #N/A
B101: Kardus Kosong Sprayer Elektrik Quda Karisma 5 L1/1/1000 | C101: 20 | E101: Akrostar 40 WP 100 X 100 gr46600 | F101: =VLOOKUP(E101,$B$2:$C$1866,2,0) -> 1349 | G101: =IF(ISNA(F101),"0",F101) -> 1349 | L101: Akrostar 40 WP 100 X 100 gr46600 | M101: =VLOOKUP(L101,lot!$A$3:$E$13372,3,0) -> #N/A | Q101: Kardus Kosong Sprayer Elektrik Quda Karisma 5 L1/1/1000 | R101: 20 | S101: #N/A | T101: =VLOOKUP(Q101,lot!$A$3:$E$13372,3,0) -> #N/A | U101: =VLOOKUP(Q101,lot!$A$3:$E$13372,5,0) -> #N/A
B102: Klep Kulit 14 ltr Star Metal1/1/1000 | C102: 78 | E102: Akrostar 40 WP 100 X 100 gr46661 | F102: =VLOOKUP(E102,$B$2:$C$1866,2,0) -> 441 | G102: =IF(ISNA(F102),"0",F102) -> 441 | L102: Akrostar 40 WP 100 X 100 gr46661 | M102: =VLOOKUP(L102,lot!$A$3:$E$13372,3,0) -> #N/A | Q102: Klep Kulit 14 ltr Star Metal1/1/1000 | R102: 78 | S102: AKLEP01 | T102: =VLOOKUP(Q102,lot!$A$3:$E$13372,3,0) -> #N/A | U102: =VLOOKUP(Q102,lot!$A$3:$E$13372,5,0) -> #N/A
B103: Klep Kulit 17 ltr Star Metal1/1/1000 | C103: 100 | E103: Akrostar 40 WP 100 X 5 gr46569 | F103: =VLOOKUP(E103,$B$2:$C$1866,2,0) -> 340 | G103: =IF(ISNA(F103),"0",F103) -> 340 | L103: Akrostar 40 WP 100 X 5 gr46569 | M103: =VLOOKUP(L103,lot!$A$3:$E$13372,3,0) -> #N/A | Q103: Klep Kulit 17 ltr Star Metal1/1/1000 | R103: 100 | S103: AKLEP02 | T103: =VLOOKUP(Q103,lot!$A$3:$E$13372,3,0) -> #N/A | U103: =VLOOKUP(Q103,lot!$A$3:$E$13372,5,0) -> #N/A
B104: Konektor Nosel Tutup1/1/1000 | C104: 40 | E104: Akrostar 40 WP 60 X 40 gr47088 | F104: =VLOOKUP(E104,$B$2:$C$1866,2,0) -> 787 | G104: =IF(ISNA(F104),"0",F104) -> 787 | L104: Akrostar 40 WP 60 X 40 gr47088 | M104: =VLOOKUP(L104,lot!$A$3:$E$13372,3,0) -> #N/A | Q104: Konektor Nosel Tutup1/1/1000 | R104: 40 | S104: AKONE01 | T104: =VLOOKUP(Q104,lot!$A$3:$E$13372,3,0) -> #N/A | U104: =VLOOKUP(Q104,lot!$A$3:$E$13372,5,0) -> #N/A
B105: Kran Pencet Star Metal1/1/1000 | C105: 476 | E105: Akrostar 40 WP 60 X 40 gr47119 | F105: =VLOOKUP(E105,$B$2:$C$1866,2,0) -> 1020 | G105: =IF(ISNA(F105),"0",F105) -> 1020 | L105: Akrostar 40 WP 60 X 40 gr47119 | M105: =VLOOKUP(L105,lot!$A$3:$E$13372,3,0) -> #N/A | Q105: Kran Pencet Star Metal1/1/1000 | R105: 476 | S105: QKRAN01 | T105: =VLOOKUP(Q105,lot!$A$3:$E$13372,3,0) -> #N/A | U105: =VLOOKUP(Q105,lot!$A$3:$E$13372,5,0) -> #N/A
B106: Laba Hidroponik 130 gr1/1/1000 | C106: 6 | E106: Alat Kocor Pupuk Cair Quda Karisma 20 ltr1/1/1000 | F106: =VLOOKUP(E106,$B$2:$C$1866,2,0) -> 258 | G106: =IF(ISNA(F106),"0",F106) -> 258 | L106: Alat Kocor Pupuk Cair Quda Karisma 20 ltr1/1/1000 | M106: =VLOOKUP(L106,lot!$A$3:$E$13372,3,0) -> #N/A | Q106: Laba Hidroponik 130 gr1/1/1000 | R106: 6 | S106: ALABA01 | T106: =VLOOKUP(Q106,lot!$A$3:$E$13372,3,0) -> #N/A | U106: =VLOOKUP(Q106,lot!$A$3:$E$13372,5,0) -> #N/A
B107: Laba Hidroponik 142 gr1/1/1000 | C107: 5 | E107: Alat Kocor Pupuk Cair Satagro 25 ltr1/1/1000 | F107: =VLOOKUP(E107,$B$2:$C$1866,2,0) -> 23 | G107: =IF(ISNA(F107),"0",F107) -> 23 | L107: Alat Kocor Pupuk Cair Satagro 25 ltr1/1/1000 | M107: =VLOOKUP(L107,lot!$A$3:$E$13372,3,0) -> #N/A | Q107: Laba Hidroponik 142 gr1/1/1000 | R107: 5 | S107: ALABA02 | T107: =VLOOKUP(Q107,lot!$A$3:$E$13372,3,0) -> #N/A | U107: =VLOOKUP(Q107,lot!$A$3:$E$13372,5,0) -> #N/A
B108: Label Piraklo 250 ml lama1/1/1000 | C108: 951 | E108: Alat Kocor Pupuk Padat Quda Karisma 25 ltr1/1/1000 | F108: =VLOOKUP(E108,$B$2:$C$1866,2,0) -> 360 | G108: =IF(ISNA(F108),"0",F108) -> 360 | L108: Alat Kocor Pupuk Padat Quda Karisma 25 ltr1/1/1000 | M108: =VLOOKUP(L108,lot!$A$3:$E$13372,3,0) -> #N/A | Q108: Label Piraklo 250 ml lama1/1/1000 | R108: 951 | S108: ALABE01 | T108: =VLOOKUP(Q108,lot!$A$3:$E$13372,3,0) -> #N/A | U108: =VLOOKUP(Q108,lot!$A$3:$E$13372,5,0) -> #N/A
B109: Label botol desanto 100 ml1/1/1000 | C109: 54 | E109: Alat Kocor Pupuk Padat Satagro 25 ltr1/1/1000 | F109: =VLOOKUP(E109,$B$2:$C$1866,2,0) -> #N/A | G109: =IF(ISNA(F109),"0",F109) -> 0 | L109: Alat Kocor Pupuk Padat Satagro 25 ltr1/1/1000 | M109: =VLOOKUP(L109,lot!$A$3:$E$13372,3,0) -> #N/A | Q109: Label botol desanto 100 ml1/1/1000 | R109: 54 | S109: ALABE02 | T109: =VLOOKUP(Q109,lot!$A$3:$E$13372,3,0) -> #N/A | U109: =VLOOKUP(Q109,lot!$A$3:$E$13372,5,0) -> #N/A
B110: Label Piraklo 250ml (Logo MIA)1/1/1000 | C110: 80 | E110: Alat Pengikat Tanaman Yoto1/1/1000 | F110: =VLOOKUP(E110,$B$2:$C$1866,2,0) -> 316 | G110: =IF(ISNA(F110),"0",F110) -> 316 | L110: Alat Pengikat Tanaman Yoto1/1/1000 | M110: =VLOOKUP(L110,lot!$A$3:$E$13372,3,0) -> #N/A | Q110: Label Piraklo 250ml (Logo MIA)1/1/1000 | R110: 80 | S110: ALABE03 | T110: =VLOOKUP(Q110,lot!$A$3:$E$13372,3,0) -> #N/A | U110: =VLOOKUP(Q110,lot!$A$3:$E$13372,5,0) -> #N/A
B111: Label botol desanto 250 ml1/1/1000 | C111: 40 | E111: Alat Service YT 5L / 7L1/1/1000 | F111: =VLOOKUP(E111,$B$2:$C$1866,2,0) -> 200 | G111: =IF(ISNA(F111),"0",F111) -> 200 | L111: Alat Service YT 5L / 7L1/1/1000 | M111: =VLOOKUP(L111,lot!$A$3:$E$13372,3,0) -> #N/A | Q111: Label botol desanto 250 ml1/1/1000 | R111: 40 | S111: ALABE04 | T111: =VLOOKUP(Q111,lot!$A$3:$E$13372,3,0) -> #N/A | U111: =VLOOKUP(Q111,lot!$A$3:$E$13372,5,0) -> #N/A
B112: Lenadro 200/70/30 OD 40 X 250 ml (Sample)47818 | C112: 1344 | E112: Alat Tanam Jagung 1 Output Satagro MTB-006 6 X 1 pcs1/1/1000 | F112: =VLOOKUP(E112,$B$2:$C$1866,2,0) -> 1278 | G112: =IF(ISNA(F112),"0",F112) -> 1278 | L112: Alat Tanam Jagung 1 Output Satagro MTB-006 6 X 1 pcs1/1/1000 | M112: =VLOOKUP(L112,lot!$A$3:$E$13372,3,0) -> #N/A | Q112: Lenadro 200/70/30 OD 40 X 250 ml (Sample)47818 | R112: 1344 | S112: ALENA01 | T112: =VLOOKUP(Q112,lot!$A$3:$E$13372,3,0) -> #N/A | U112: =VLOOKUP(Q112,lot!$A$3:$E$13372,5,0) -> #N/A
...

Sheet barang_no_qr
B1: a | C1: v | D1: b | E1: c | F1: f
B2: Accu Kayaba Kering 12A - 12 Volt1/1/1000 | C2: 1 | D2: AACCU01 | E2: Accu Kayaba Kering 12A - 12 Volt | F2: =VLOOKUP(B2,lot!$A$3:$E$13372,5,0) -> #N/A
B3: Adrift 125 EC 50 X 100 ml46813 | C3: 202 | D3: QADRI01 | E3: Adrift 125 EC 50 X 100 ml | F3: =VLOOKUP(B3,lot!$A$3:$E$13372,5,0) -> #N/A
B4: Alat Kocor Pupuk Cair Quda Karisma 20 ltr1/1/1000 | C4: 258 | D4: QALAT07 | E4: Alat Kocor Pupuk Cair Quda Karisma 20 ltr | F4: =VLOOKUP(B4,lot!$A$3:$E$13372,5,0) -> #N/A
